Workbook

Sheet Venues
A1: VID | B1: Name | C1: Publisher | D1: Type
A3: 1 | B3: IEEE Transactions on Services Computing | C3: IEEE | D3: Journal
A4: 2 | B4: Journal of Grid Computing | C4: Springer | D4: Journal
A5: 3 | B5: IEEE Transactions on Parallel and Distributed Systems | C5: IEEE | D5: Journal
A6: 4 | B6: IEEE Transactions on Network and Service Management | C6: IEEE | D6: Journal
A7: 5 | B7: IEEE Access | C7: IEEE | D7: Journal
A8: 6 | B8: IEEE Transactions on Cloud Computing | C8: IEEE | D8: Journal
A9: 7 | B9: The Journal of Supercomputing | C9: Springer | D9: Journal
A10: 8 | B10: Computers and Industrial Engineering | C10: Elsevier | D10: Journal
A11: 9 | B11: Soft Computing | C11: Springer | D11: Journal
A12: 10 | B12: International Journal of Web Services Research | C12: IGI Global | D12: Journal
A13: 11 | B13: Future Generation Computer Systems | C13: Elsevier | D13: Journal
A14: 12 | B14: Journal of Ambient Intelligence and Humanized Computing | C14: Springer | D14: Journal
... A45: 43 | B45: International Conference on Service Science (CLOSER) | C45: Springer | D45: Conference

Sheet Papers
A1: PID | B1: VID | C1: Title | D1: Year | E1: Algorithm Name | F1: BibTex | G1: Publisher
A3: 1 | B3: =Venues!A3 -> 1 | C3: A Cloud Broker for Executing Deadline-Constrained Periodic Scientific Workflows | D3: 2023 | E3: cloud Broker for executing Deadline-constrained Periodic scientific Workflows (BDPW) | F3: article{1, author={Taheri, Hoda and Abrishami, Saeid and Naghibzadeh, Mahmoud}, journal={IEEE Transactions on Services Computing}, title={A Cloud Broker for Executing Deadline-Constrained Periodic Scientific Workflows}, year={2023}, volume={16}, number={5}, pages={3089-3100}, keywords={Task analysis;Cloud computing;Costs;Dynamic scheduling;Containers;Heuristic algorithms;Computational modeling;Cloud brokerage;periodic scientific workflows;multiple workflows scheduling;resource reservation;WaaS}, doi={10.1109/TSC.2023.3284492}} | G3: {=INDIRECT("Venues!C" & MATCH(B3,Venues!A:A,0))} -> IEEE
A4: 2 | B4: =Venues!A4 -> 2 | C4: A Cost-Efficient Workflow as a Service Broker Using On-demand and Spot Instances | D4: 2023 | E4: Cost Efficient Workflow-as-a-Service Broker (CEWB) | F4: article{2, author={Taghavi, Bahareh and Zolfaghari, Behrooz and Abrishami, Saeid}, journal={Journal of Grid Computing}, title={A Cost-Efficient Workflow as a Service Broker Using On-demand and Spot Instances}, year={2023}, volume={21}, number={40}, pages={}, doi={10.1007/s10723-023-09676-9}} | G4: {=INDIRECT("Venues!C" & MATCH(B4,Venues!A:A,0))} -> Springer
A5: 3 | B5: =Venues!A5 -> 3 | C5: Multi-Swarm Co-Evolution Based Hybrid Intelligent Optimization for Bi-Objective Multi-Workflow Scheduling in the Cloud | D5: 2022 | E5: Multi-swarm Co-evolution-based Hybrid intelligent Optimization (MCHO) | F5: article{3, author={Li, Huifang and Wang, Danjing and Zhou, MengChu and Fan, Yushun and Xia, Yuanqing}, journal={IEEE Transactions on Parallel and Distributed Systems}, title={Multi-Swarm Co-Evolution Based Hybrid Intelligent Optimization for Bi-Objective Multi-Workflow Scheduling in the Cloud}, year={2022}, volume={33}, number={9}, pages={2183-2197}, keywords={Task analysis;Cloud computing;Costs;Optimization;Heuristic algorithms;Quality of service;Dynamic scheduling;Cloud computing;intelligent optimization;multi-swarm;multiple workflows;Quality of Service (QoS);scheduling}, doi={10.1109/TPDS.2021.3122428}} | G5: {=INDIRECT("Venues!C" & MATCH(B5,Venues!A:A,0))} -> IEEE
A6: 4 | B6: =Venues!A3 -> 1 | C6: Uncertainty-Aware Online Scheduling for Real-Time Workflows in Cloud Service Environment | D6: 2018 | E6: unceRtainty-aware Online Scheduling Algorithm (ROSA) | F6: article{4, author={Chen, Huangke and Zhu, Xiaomin and Liu, Guipeng and Pedrycz, Witold}, journal={IEEE Transactions on Services Computing}, title={Uncertainty-Aware Online Scheduling for Real-Time Workflows in Cloud Service Environment}, year={2021}, volume={14}, number={4}, pages={1167-1178}, keywords={Task analysis;Cloud computing;Data transfer;Uncertainty;Schedules;Computer architecture;Scheduling;Workflow scheduling;uncertain;proactive and reactive strategies;cloud service}, doi={10.1109/TSC.2018.2866421}} | G6: {=INDIRECT("Venues!C" & MATCH(B6,Venues!A:A,0))} -> IEEE
A7: 5 | B7: =Venues!A3 -> 1 | C7: Resource Renting for Periodical Cloud Workflow Applications | D7: 2020 | E7: Precedence Tree-based Heuristic (PTH) | F7: article{5, author={Chen, Long and Li, Xiaoping and Ruiz, Rubén}, journal={IEEE Transactions on Services Computing}, title={Resource Renting for Periodical Cloud Workflow Applications}, year={2020}, volume={13}, number={1}, pages={130-143}, keywords={Cloud computing;Processor scheduling;Scheduling;Schedules;Quality of service;Minimization;Partitioning algorithms;Resource allocation;long-term resources renting;periodical multiple workflows;cloud computing}, doi={10.1109/TSC.2017.2677450}} | G7: {=INDIRECT("Venues!C" & MATCH(B7,Venues!A:A,0))} -> IEEE
A8: 6 | B8: =Venues!A6 -> 4 | C8: Real-Time Multiple-Workflow Scheduling in Cloud Environments | D8: 2021 | F8: article{6, author={Ma, Xiaojin and Xu, Huahu and Gao, Honghao and Bian, Minjie}, journal={IEEE Transactions on Network and Service Management}, title={Real-Time Multiple-Workflow Scheduling in Cloud Environments}, year={2021}, volume={18}, number={4}, pages={4002-4018}, keywords={Task analysis;Cloud computing;Processor scheduling;Costs;Real-time systems;Dynamic scheduling;Schedules;Cloud computing;multiple workflows;online scheduling;VM optimization}, doi={10.1109/TNSM.2021.3125395}} | G8: {=INDIRECT("Venues!C" & MATCH(B8,Venues!A:A,0))} -> IEEE
A9: 7 | B9: =Venues!A7 -> 5 | C9: Multi-Objective Workflow Scheduling With Deep-Q-Network-Based Multi-Agent Reinforcement Learning | D9: 2019 | E9: deep-Q-network based Multi Agent Reinforcement Learning (MARL) | F9: article{7, author={Wang, Yuandou and Liu, Hang and Zheng, Wanbo and Xia, Yunni and Li, Yawen and Chen, Peng and Guo, Kunyin and Xie, Hong}, journal={IEEE Access}, title={Multi-Objective Workflow Scheduling With Deep-Q-Network-Based Multi-Agent Reinforcement Learning}, year={2019}, volume={7}, number={}, pages={39974-39982}, keywords={Optimal scheduling;Games;Task analysis;Cloud computing;Reinforcement learning;Markov processes;Scheduling;Multi-objective workflow scheduling;deep-Q-network (DQN);multi-agent reinforcement learning (MARL);infrastructure-as-a-service (IaaS) cloud;quality-of-service (QoS)}, doi={10.1109/ACCESS.2019.2902846}} | G9: {=INDIRECT("Venues!C" & MATCH(B9,Venues!A:A,0))} -> IEEE
A10: 8 | B10: =Venues!A8 -> 6 | C10: Online Multi-Workflow Scheduling under Uncertain Task Execution Time in IaaS Clouds | D10: 2019 | E10: onliNe multi-wOrkflow Scheduling Framework (NOSF) | F10: article{8, author={Liu, Jiagang and Ren, Ju and Dai, Wei and Zhang, Deyu and Zhou, Pude and Zhang, Yaoxue and Min, Geyong and Najjari, Noushin}, journal={IEEE Transactions on Cloud Computing}, title={Online Multi-Workflow Scheduling under Uncertain Task Execution Time in IaaS Clouds}, year={2021}, volume={9}, number={3}, pages={1180-1194}, keywords={Task analysis;Cloud computing;Scheduling;Processor scheduling;Resource management;Stochastic processes;Pricing;Cloud computing;workflow scheduling;VM rental cost;uncertain task execution time;multiple workflows}, doi={10.1109/TCC.2019.2906300}} | G10: {=INDIRECT("Venues!C" & MATCH(B10,Venues!A:A,0))} -> IEEE
A11: 9 | B11: =Venues!A8 -> 6 | C11: Reliability, Rental-Cost and Energy-Aware Multi-Workflow Scheduling on Multi-Cloud Systems | D11: 2022 | E11: Reliability, rental cost and Energy-aware Multi-workflow Scheduling in the Multi-Cloud (REMSM) | F11: article{9, author={Taghinezhad-Niar, Ahmad and Taheri, Javid}, journal={IEEE Transactions on Cloud Computing}, title={Reliability, Rental-Cost and Energy-Aware Multi-Workflow Scheduling on Multi-Cloud Systems}, year={2023}, volume={11}, number={3}, pages={2681-2692}, keywords={Reliability;Cloud computing;Task analysis;Scheduling;Costs;Energy consumption;Behavioral sciences;Energy;multi-cloud;multi-workflow;reliability;scheduling}, doi={10.1109/TCC.2022.3223869}} | G11: {=INDIRECT("Venues!C" & MATCH(B11,Venues!A:A,0))} -> IEEE
A12: 10 | B12: =Venues!A9 -> 7 | C12: A cost and makespan aware scheduling algorithm for dynamic multi-workflow in cloud environment | D12: 2023 | E12: Multi-workflow scheduling Technology (MT) | F12: article{10, author={Xia, Yuanqing and Zhan, Yufeng and Dai, Li and Chen, Yuehong}, journal={The Journal of Supercomputing}, title={A cost and makespan aware scheduling algorithm for dynamic }, year={2023}, volume={79}, number={2}, pages={1814-1833}, doi={10.1007/s11227-022-04681-3}} | G12: {=INDIRECT("Venues!C" & MATCH(B12,Venues!A:A,0))} -> Springer
A13: 11 | B13: =Venues!A10 -> 8 | C13: Uncertainty-aware online deadline-constrained scheduling of parallel applications in distributed heterogeneous systems | D13: 2024 | E13: Online Parallel Applications Deadline-Constrained Scheduling algorithm (OPADCS) | F13: article{11, title = {Uncertainty-aware online deadline-constrained scheduling of parallel applications in distributed heterogeneous systems}, journal = {Computers & Industrial Engineering}, volume = {196}, pages = {110450}, year = {2024}, issn = {0360-8352}, doi = {https://doi.org/10.1016/j.cie.2024.110450}, url = {https://www.sciencedirect.com/science/article/pii/S0360835224005710}, author = {Yifan Liu and Jinchao Chen and Jiangong Yang and Chenglie Du and Xiaoyan Du}, keywords = {Online scheduling, Deadline constrained, Dynamic systems, Distributed heterogeneous systems, Uncertainty-aware}, abstract = {Parallel application scheduling with deadline constraints is a crucial area in distributed heterogeneous systems, and various methodologies have been proposed. However, these approaches overlook the uncertainty of task execution times and the randomness of application arrivals. Therefore, this study aims to solve the online scheduling problem of parallel applications with deadline constraints by introducing a novel algorithm that addresses uncertainties. We develop a model for randomly arriving applications and introduce a dynamic task prioritization strategy to mitigate uncertainty. Additionally, we augment with a discard mechanism to bolster application success rates. We conducted nine groups of experiments using both randomly generated applications and real-world applications. Simulation results demonstrate that the proposed algorithm significantly outperforms three similar algorithms in terms of enhancing DAG success rate, resource utilization, and runtime efficiency.} } | G13: {=INDIRECT("Venues!C" & MATCH(B13,Venues!A:A,0))} -> Elsevier
A14: 12 | B14: =Venues!A9 -> 7 | C14: Cost-efficient reactive scheduling for real-time workflows in clouds | D14: 2018 | E14: Cost-Efficient Reactive Scheduling Algorithm (CERSA) | F14: article{12, author={Chen, Huangke and Zhu, Jianghan and Wu, Guohua and Huo, Lisu}, journal={The Journal of Supercomputing}, title={Cost-efficient reactive scheduling for real-time workflows in clouds}, year={2018}, volume={74}, number={11}, pages={6291-6309}, doi={10.1007/s11227-018-2561-9}} | G14: {=INDIRECT("Venues!C" & MATCH(B14,Venues!A:A,0))} -> Springer
A15: 13 | B15: =Venues!A9 -> 7 | C15: A flexible deadline-driven resource provisioning and scheduling algorithm for multiple workflows with VM sharing protocol on WaaS-cloud | D15: 2022 | E15: Flexible Deadline-driven resource Provisioning and scheduling algorithm for Multiple workfows (FDPM) | F15: article{13, author={Rajasekar, P. and Palanichamy, Yogesh}, journal={The Journal of Supercomputing}, title={A flexible deadline-driven resource provisioning and scheduling algorithm for multiple workflows with VM sharing protocol on WaaS-cloud}, year={2022}, volume={78}, number={6}, pages={8025-8085}, doi={10.1007/s11227-021-04225-1}} | G15: {=INDIRECT("Venues!C" & MATCH(B15,Venues!A:A,0))} -> Springer
A16: 14 | B16: =Venues!A11 -> 9 | C16: Concurrent workflow budget- and deadline-constrained scheduling in heterogeneous distributed environments | D16: 2018 | E16: Multi-Workflow Heterogeneous Budget- and Deadline-Constrained Scheduling algorithm (MW-HBDCS) | F16: article{14, author={Zhou, Naqin and Li, FuFang and Xu, Kefu and Qi, Deyu}, journal={Soft Computing}, title={Concurrent workflow budget- and deadline-constrained scheduling in heterogeneous distributed environments}, year={2018}, volume={22}, number={23}, pages={7705-7718}, doi={10.1007/s00500-018-3229-3}} | G16: {=INDIRECT("Venues!C" & MATCH(B16,Venues!A:A,0))} -> Springer
A17: 15 | B17: =Venues!A9 -> 7 | C17: Fair multiple-workflow scheduling with different quality-of-service goals | D17: 2019 | F17: article{15, author={Rezaeian, Amin and Naghibzadeh, Mahmoud and Epema, Dick H. J.}, journal={The Journal of Supercomputing}, title={Fair multiple-workflow scheduling with different quality-of-service goals}, year={2019}, volume={75}, number={2}, pages={746-769}, doi={10.1007/s11227-018-2604-2}} | G17: {=INDIRECT("Venues!C" & MATCH(B17,Venues!A:A,0))} -> Springer
A18: 16 | B18: =Venues!A5 -> 3 | C18: Scheduling Periodical Multi-Stage Jobs With Fuzziness to Elastic Cloud Resources | D18: 2020 | E18: Fuzzy Dynamic Event Scheduling framework (FDES) and Fuzzy Task Scheduling (FTS) | F18: article{16, author={Zhu, Jie and Li, Xiaoping and Ruiz, Rubén and Li, Wei and Huang, Haiping and Zomaya, Albert Y.}, journal={IEEE Transactions on Parallel and Distributed Systems}, title={Scheduling Periodical Multi-Stage Jobs With Fuzziness to Elastic Cloud Resources}, year={2020}, volume={31}, number={12}, pages={2819-2833}, keywords={Task analysis;Dynamic scheduling;Job shop scheduling;Cloud computing;Schedules;Heuristic algorithms;Job scheduling;fuzzy processing times;fuzzy deadlines;cloud computing}, doi={10.1109/TPDS.2020.3004134}} | G18: {=INDIRECT("Venues!C" & MATCH(B18,Venues!A:A,0))} -> IEEE
A19: 17 | B19: =Venues!A12 -> 10 | C19: Scheduling Multi-Workflows Over Heterogeneous Virtual Machines With a Multi-Stage Dynamic Game-Theoretic Approach | D19: 2018 | E19: Multi-stage Dynamic Game-Theoretic (MDGT) | F19: article{17, author={Wu, Lei and Yuandou, Wang}, journal={International Journal of Web Services Research}, title={Scheduling Multi-Workflows Over Heterogeneous Virtual Machines With a Multi-Stage Dynamic Game-Theoretic Approach}, year={2018}, volume={15}, number={4}, pages={82-96}, doi={10.4018/IJWSR.2018100105}} | G19: {=INDIRECT("Venues!C" & MATCH(B19,Venues!A:A,0))} -> IGI Global
A20: 18 | B20: =Venues!A3 -> 1 | C20: Scheduling Constrained Cloud Workflow Tasks via Evolutionary Multitasking Optimization With Adaptive Knowledge Transfer | D20: 2024 | E20: Evolutionary Multitasking Constrained Optimization-Adaptive Double-level knowledge Transfer (EMCO-ADT) Evolutionary Multitasking Constrained Optimization-Adaptive Double-level knowledge Transfer (EMCO-ADT) | F20: article{18, author={Zhou, Jiajun and Gao, Liang and Rao, Shijie and Li, Yun}, journal={ IEEE Transactions on Services Computing }, title={{ Scheduling Constrained Cloud Workflow Tasks via Evolutionary Multitasking Optimization With Adaptive Knowledge Transfer }}, year={2024}, volume={17}, number={06}, ISSN={1939-1374}, pages={4254-4266}, abstract={ Cloud workflow scheduling (CWS) is critical for meeting user's high performance expectations in large-scale data processing and computing applications. CWS is known to be NP-hard and needs advanced scheduling techniques. Evolutionary algorithm and heuristic-based search techniques have gained massive popularity in addressing CWS, yet they either suffer from expensive computational cost or heavily rely on domain-specific experiences, which limit their practical applications. Bearing this in mind, we develop a novel evolutionary multi-task optimization framework to tackle a group of constrained CWS tasks simultaneously with the aid of adaptive cross-task problem-solving knowledge transfer. In particular, two collaborative knowledge exchange strategies, namely, constraint-free archive strategy and cross-task evolution strategy, are devised to extract useful building blocks from foreign tasks to boost the search efficiency. Further, to leverage the cooperative effects of both strategies, we develop an adaptive switching mechanism such that appropriate knowledge transfer strategies are learned automatically according to the population evolution status. Extensive experiments are conducted on real-world applications under various conditions, the comparison results show that our proposal delivers higher quality schedules than the state-of-the-art competitors in most cases. }, keywords={Processor scheduling;Search problems;Problem-solving;Optimal scheduling;Heuristic algorithms;Genetic algorithms;Costs}, doi={10.1109/TSC.2024.3463423}, url = {https://doi.ieeecomputersociety.org/10.1109/TSC.2024.3463423}, publisher={IEEE Computer Society}, address={Los Alamitos, CA, USA}, month=nov} | G20: {=INDIRECT("Venues!C" & MATCH(B20,Venues!A:A,0))} -> IEEE
A21: 19 | B21: =Venues!A13 -> 11 | C21: Scheduling dynamic workloads in multi-tenant scientific workflow as a service platforms | D21: 2018 | E21: Elastic resource Provisioning and Scheduling algorithm for Multiple workflows (EPSM) | F21: article{19, title = {Scheduling dynamic workloads in multi-tenant scientific workflow as a service platforms}, journal = {Future Generation Computer Systems}, volume = {79}, pages = {739-750}, year = {2018}, issn = {0167-739X}, doi = {https://doi.org/10.1016/j.future.2017.05.009}, url = {https://www.sciencedirect.com/science/article/pii/S0167739X17301681}, author = {Maria A. Rodriguez and Rajkumar Buyya}, keywords = {Cloud computing, Cost minimization, Deadline, Workflow as a service, Resource provisioning, Scheduling}, abstract = {With the advent of cloud computing and the availability of data collected from increasingly powerful scientific instruments, workflows have become a prevailing mean to achieve significant scientific advances at an increased pace. Emerging Workflow as a Service (WaaS) platforms offer scientists a simple, easily accessible, and cost-effective way of deploying their applications in the cloud at anytime and from anywhere. They are multi-tenant frameworks and are designed to manage the execution of a continuous workload of heterogeneous workflows. To achieve this, they leverage the compute, storage, and network resources offered by Infrastructure as a Service (IaaS) providers. Hence, at any given point in time, a WaaS platform should be capable of efficiently scheduling an arbitrarily large number of workflows with different characteristics and quality of service requirements. As a result, we propose a resource provisioning and scheduling strategy designed specifically for WaaS environments. The algorithm is scalable and dynamic to adapt to changes in the environment and workload. It leverages containers to address resource utilization inefficiencies and aims to minimize the overall cost of leasing the infrastructure resources while meeting the deadline constraint of each individual workflow. To the best of our knowledge, this is the first approach that explicitly addresses VM sharing in the context of WaaS by modeling the use of containers in the resource provisioning and scheduling heuristics. Our simulation results demonstrate its responsiveness to environmental uncertainties, its ability to meet deadlines, and its cost-efficiency when compared to a state-of-the-art algorithm.} } | G21: {=INDIRECT("Venues!C" & MATCH(B21,Venues!A:A,0))} -> Elsevier
A22: 20 | B22: =Venues!A13 -> 11 | C22: A multi-class workflow ensemble management system using on-demand and spot instances in cloud | D22: 2022 | E22: Multi-class Workflow Ensemble Sched_x0002_uling (MWEM) | F22: article{20, title = {A multi-class workflow ensemble management system using on-demand and spot instances in cloud}, journal = {Future Generation Computer Systems}, volume = {137}, pages = {97-110}, year = {2022}, issn = {0167-739X}, doi = {https://doi.org/10.1016/j.future.2022.07.007}, url = {https://www.sciencedirect.com/science/article/pii/S0167739X22002369}, author = {Behrooz Zolfaghari and Saeid Abrishami}, keywords = {Cloud computing, Resource provisioning, Task scheduling, Spot instances, Workflow ensemble, Scientific Workflows}, abstract = {Nowadays, cloud computing is an attractive and competitive market, and many computational jobs have migrated to cloud resources. Scheduling a workflow is a common issue in cloud computing. In some applications, a group of interrelated workflows with the same structure but different sizes and inputs is considered as a single job called an ensemble. Executing such applications in the cloud is expensive, and designing a cost-efficient approach is still challenging. The current paper proposes a new algorithm for scheduling workflow ensembles that are subject aware to of budget and deadline constraints. To achieve this aim, the present study takes advantage of Amazon spot instances. These instances are offered by bid at a lower price but with lower reliability. In the proposed algorithm, workflow tasks are classified according to deadlines and priorities, and the requested spot instances are classified based on bid prices. More reliable instances with higher bid prices are assigned to more important classes of tasks. Furthermore, an efficient workflow acceptance and instance provisioning procedure are proposed to launch and terminate instances based on the number of ready tasks and their deadlines. The present research’s simulation results show that the proposed system increases the number of completed workflows and reduces the number of partially executed ones.} } | G22: {=INDIRECT("Venues!C" & MATCH(B22,Venues!A:A,0))} -> Elsevier
A23: 21 | B23: =Venues!A13 -> 11 | C23: Algorithms for cost- and deadline-constrained provisioning for scientific workflow ensembles in IaaS clouds | D23: 2015 | E23: Dynamic Provisioning Dynamic Scheduling (DPDS) and Workflow Aware DPDS (WA-DPDS) | F23: article{21, title = {Algorithms for cost- and deadline-constrained provisioning for scientific workflow ensembles in IaaS clouds}, journal = {Future Generation Computer Systems}, volume = {48}, pages = {1-18}, year = {2015}, note = {Special Section: Business and Industry Specific Cloud}, issn = {0167-739X}, doi = {https://doi.org/10.1016/j.future.2015.01.004}, url = {https://www.sciencedirect.com/science/article/pii/S0167739X15000059}, author = {Maciej Malawski and Gideon Juve and Ewa Deelman and Jarek Nabrzyski}, keywords = {Scientific workflows, Workflow ensembles, Cloud computing, Resource provisioning}, abstract = {Large-scale applications expressed as scientific workflows are often grouped into ensembles of inter-related workflows. In this paper, we address a new and important problem concerning the efficient management of such ensembles under budget and deadline constraints on Infrastructure as a Service (IaaS) clouds. IaaS clouds are characterized by on-demand resource provisioning capabilities and a pay-per-use model. We discuss, develop, and assess novel algorithms based on static and dynamic strategies for both task scheduling and resource provisioning. We perform the evaluation via simulation using a set of scientific workflow ensembles with a broad range of budget and deadline parameters, taking into account task granularity, uncertainties in task runtime estimations, provisioning delays, and failures. We find that the key factor determining the performance of an algorithm is its ability to decide which workflows in an ensemble to admit or reject for execution. Our results show that an admission procedure based on workflow structure and estimates of task runtimes can significantly improve the quality of solutions.} } | G23: {=INDIRECT("Venues!C" & MATCH(B23,Venues!A:A,0))} -> Elsevier
A24: 21-b | E24: Static Provisioning Static Scheduling (SPSS)
A25: 22 | B25: =Venues!A14 -> 12 | C25: Scheduling multiple scientific workflows using containers on IaaS cloud | D25: 2021 | E25: Scalable Resource Provisioning and Scheduling algorithm for Multiple workfows (SRPSM) | F25: article{22, author={Rajasekar, P. and Palanichamy, Yogesh}, journal={Journal of Ambient Intelligence and Humanized Computing}, title={Scheduling multiple scientific workflows using containers on IaaS cloud}, year={2021}, volume={12}, number={7}, pages={7621-7636}, doi={10.1007/s12652-020-02483-0}} | G25: {=INDIRECT("Venues!C" & MATCH(B25,Venues!A:A,0))} -> Springer
A26: 23 | B26: =Venues!A13 -> 11 | C26: Dynamic multi-workflow scheduling: A deadline and cost-aware approach for commercial clouds | D26: 2019 | E26: Dynamic Workflow Scheduler (DWS) | F26: article{23, title = {Dynamic multi-workflow scheduling: A deadline and cost-aware approach for commercial clouds}, journal = {Future Generation Computer Systems}, volume = {100}, pages = {98-108}, year = {2019}, issn = {0167-739X}, doi = {https://doi.org/10.1016/j.future.2019.04.029}, url = {https://www.sciencedirect.com/science/article/pii/S0167739X18307386}, author = {Vahid Arabnejad and Kris Bubendorfer and Bryan Ng}, abstract = {Cloud computing, specifically its elastic, on demand, and pay per use instances, provide an ideal model for resourcing large scale state-of-the-art scientific analyses. Such scientific work is typically represented as workflows — the most common model for characterizing e-Science experiments and data analysis. Hosting and managing scientific applications on the cloud poses new challenges in terms of workflow scheduling which is key in leveraging its inherent cost and performance benefits. Prior research has studied static scheduling when the number of workflows is known in advance and all are submitted at the same time. However, in practice, a scheduler may have to schedule an unpredictable stream of workflows, for example, recent workflow management systems — such as Parsl, do not construct complete workflows at any stage during their execution, rather they generate partial workflows dynamically during execution — somewhat akin to lazy evaluation. This change in the way in which scientific data and workflows are created and processed represents a disruptive change to the way in which scheduling needs to occur. This paper represents a first and necessary step towards addressing scheduling problems of this nature, in which we present a new algorithm, Dynamic Workload Scheduler (DWS) that handles the dynamics of multiple deadline constrained workflows arriving randomly and scheduling these workflows with reducing cost in mind. Our results show that the DWS algorithm achieves an average 10% higher success rate in terms of fulfilling deadlines for different workloads and reduces the overall cost by an average 23% when compared to the most recent comparable algorithm.} } | G26: {=INDIRECT("Venues!C" & MATCH(B26,Venues!A:A,0))} -> Elsevier
A27: 24 | B27: =Venues!A15 -> 13 | C27: QoS-aware online scheduling of multiple workflows under task execution time uncertainty in clouds | D27: 2022 | E27: Energy and Uncertain task exection time aware workflow Scheduling Framework (EUSF) | F27: article{24, author={Taghinezhad-Niar, Ahmad and Pashazadeh, Saeid and Taheri, Javid}, journal={Cluster Computing}, title={QoS-aware online scheduling of multiple workflows under task execution time uncertainty in clouds}, year={2022}, volume={25}, number={6}, pages={3767-3784}, doi={10.1007/s10586-022-03600-8}} | G27: {=INDIRECT("Venues!C" & MATCH(B27,Venues!A:A,0))} -> Springer
A28: 25 | B28: =Venues!A16 -> 14 | C28: Cloud Computing: A Multi-workflow Scheduling Algorithm with Dynamic Reusability | D28: 2018 | E28: Competent Dynamic Multi-Workflow Scheduling (CDMWS) | F28: article{25, author={Adhikari, Mainak and Koley, Santanu}, journal={Arabian Journal for Science and Engineering}, title={Cloud Computing: A Multi-workflow Scheduling Algorithm with Dynamic Reusability}, year={2018}, volume={43}, number={2}, pages={645-660}, doi={10.1007/s13369-017-2739-0}} | G28: {=INDIRECT("Venues!C" & MATCH(B28,Venues!A:A,0))} -> Springer
A29: 26 | B29: =Venues!A17 -> 15 | C29: TOPSIS inspired Budget and Deadline Aware Multi-Workflow Scheduling for Cloud computing | D29: 2021 | E29: TOPSIS inspired Budget and Deadline aware Multi-Workflow Scheduling algorithm (T-BDMWS) | F29: article{26, title = {TOPSIS inspired Budget and Deadline Aware Multi-Workflow Scheduling for Cloud computing}, journal = {Journal of Systems Architecture}, volume = {114}, pages = {101916}, year = {2021}, issn = {1383-7621}, doi = {https://doi.org/10.1016/j.sysarc.2020.101916}, url = {https://www.sciencedirect.com/science/article/pii/S138376212030179X}, author = {Koneti Kalyan Chakravarthi and L. Shyamala}, keywords = {TOPSIS, Quality of service, Budget, Deadline, Scheduling, Multiple workflows}, abstract = {Scheduling is a decision-making mechanism that allows resource sharing among several activities by determining their order of execution on the available resources. In the heterogeneous distributed systems, it is a great challenge to schedule concurrent workflows submitted by different users at different times. Scheduling with deadline and budget constraints are becoming an even more challenging issue for cloud systems due to the cloud dynamics such as on-demand provisioning, elasticity, abundant resource types, and various pricing schemes. A well-managed budget and deadline constraint scheduling is required to optimize the system performance and end-user satisfaction. Hence, improving system performance and optimizing multiple scheduling criteria at the same time is a big challenge. To address these issues, a novel multi-workflow scheduling algorithm based on the Multi-Criteria Decision Making (MCDM) approach, TOPSIS (Technique of Order Preference by Similarity to Ideal Solution) is presented. A weighted sum of run time, cost and data transfer time are used to determine the optimal resource among the available resources in accordance with the task requirements. The performance of the proposed algorithm is compared with the state-of-the-art algorithms such as Budget-Heterogeneous Earliest Finish Time (BHEFT), Budget and Deadline Constraint Heterogeneous Earliest Finish Time (BDHEFT) and Cloud-based Workflow Scheduling Algorithm (CWSA) algorithms based on budget constraint,deadline constraint, and resource utilization. The experimental results demonstrate that the proposed T-BDMWS outperforms current state-of-the-art heuristics with the criteria of achieving the user-specified budget or deadline constraints and resource efficiency.} } | G29: {=INDIRECT("Venues!C" & MATCH(B29,Venues!A:A,0))} -> Elsevier
A30: 27 | B30: =Venues!A18 -> 16 | C30: Maximizing the completion rate of concurrent scientific applications under time and budget constraints | D30: 2017 | E30: Multi-Workflow Deadline-Budget Scheduling algorithm (MWDBS) | F30: article{27, title = {Maximizing the completion rate of concurrent scientific applications under time and budget constraints}, journal = {Journal of Computational Science}, volume = {23}, pages = {120-129}, year = {2017}, issn = {1877-7503}, doi = {https://doi.org/10.1016/j.jocs.2016.10.013}, url = {https://www.sciencedirect.com/science/article/pii/S1877750316302447}, author = {Hamid Arabnejad and Jorge G. Barbosa}, keywords = {Concurrent jobs, Workflow applications, Clouds, Grids}, abstract = {In many domains of science, scientific applications are represented by workflows. In this paper, we introduce a resource management strategy to maximize the success rate of concurrent workflow applications constrained by individual deadline and budget values. The Multi-Workflow Deadline-Budget Scheduling (MW-DBS) algorithm can schedule multiple workflows that can arrive in the system at any time, with the aim of satisfying individual job requirements. MW-DBS produces schedules without performing optimizations but guarantees that the deadline and budget defined for each job are not exceeded. Experimental results show that our strategy increases the scheduling success rate of finding valid solutions.} } | G30: {=INDIRECT("Venues!C" & MATCH(B30,Venues!A:A,0))} -> Elsevier
A31: 28 | B31: =Venues!A13 -> 11 | C31: Multi-QoS constrained and Profit-aware scheduling approach for concurrent workflows on heterogeneous systems | D31: 2017 | E31: Multi-QoS Profit-Aware Scheduling algorithm (MQ-PAS) | F31: article{28, title = {Multi-QoS constrained and Profit-aware scheduling approach for concurrent workflows on heterogeneous systems}, journal = {Future Generation Computer Systems}, volume = {68}, pages = {211-221}, year = {2017}, issn = {0167-739X}, doi = {https://doi.org/10.1016/j.future.2016.10.003}, url = {https://www.sciencedirect.com/science/article/pii/S0167739X16303740}, author = {Hamid Arabnejad and Jorge G. Barbosa}, keywords = {Quality of service, On-line scheduling, Deadline, Budget}, abstract = {The execution of a workflow application can result in an imbalanced workload among allocated processors, ultimately resulting in a waste of resources and a higher cost to the user. Here, we consider a dynamic resource management system in which processors are reserved not for a job but only to run a task, thus allowing a higher resource usage rate. This paper presents a scheduling algorithm that manages concurrent workflows in a dynamic environment in which jobs are submitted by users at any moment in time, on shared heterogeneous resources, and constrained to a specified budget and deadline for each job. Recent research attempted to propose dynamic strategies for concurrent workflows but only addressed fairness in resource sharing among applications while minimizing the execution time. The Multi-QoS Profit-Aware scheduling algorithm (MQ-PAS) proposed here is able to increase the profit achieved by the provider by considering the budget available for each job to define tasks priorities. We study the scalability of the algorithm with different types of workflows and infrastructures. The experimental results show that our strategy improves provider revenue significantly and obtains comparable successful rates of completed jobs.} } | G31: {=INDIRECT("Venues!C" & MATCH(B31,Venues!A:A,0))} -> Elsevier
A32: 29 | B32: =Venues!A19 -> 17 | C32: TOPSIS inspired cost-efficient concurrent workflow scheduling algorithm in cloud | D32: 2022 | E32: TOPSIS inspired Cost-efficient Concurrent Workflow Scheduling Algorithm (T-CCWSA) | F32: article{29, title = {TOPSIS inspired cost-efficient concurrent workflow scheduling algorithm in cloud}, journal = {Journal of King Saud University - Computer and Information Sciences}, volume = {34}, number = {6, Part A}, pages = {2359-2369}, year = {2022}, issn = {1319-1578}, doi = {https://doi.org/10.1016/j.jksuci.2020.02.006}, url = {https://www.sciencedirect.com/science/article/pii/S1319157820303207}, author = {K. Kalyan Chakravarthi and L. Shyamala and V. Vaidehi}, keywords = {TOPSIS, Quality of Service, Deadline, Scheduling, Concurrent Workflows}, abstract = {Scheduling is a decision-making mechanism that enables the sharing of resources among several activities by determining their execution order on the set of available resources. In distributed systems, it is a great challenge to schedule multiple workflows submitted at different times. In particular, concurrent workflow scheduling with time constraints makes the problem more complex in the cloud due to the dynamics of the cloud such as elasticity, non-homogeneous resource types, various pricing schemes, and virtualization. A well-managed deadline workflow scheduling is required to improve end-user satisfaction and system performance. In the meantime, the intrinsic uncertainty in the cloud increases the difficulties of scheduling problems. Therefore, it is a great challenge to improve system performance and optimize several scheduling criteria simultaneously. To address the above issues, a novel concurrent workflow scheduling method for heterogeneous distributed environments based on the new Multi-Criteria Decision Making (MCDM) method i.e., TOPSIS (Technique of Order Preference by Similarity to Ideal Solution) is presented. A weighted sum of execution time, cost and communication time are used to find out the optimal resource among the existing resources as per the workflow task requirements. The proposed method minimizes the makespan and execution cost of the workflow and improves the resource efficiency under uncertain environment. The performance of the proposed work is compared with the state-of-the-art algorithms such as Cloud-based Workflow Scheduling Algorithm (CWSA), Earliest Finish Time-Maximum Effective Reduction (EFT-MER) and Heterogeneous Earliest-Finish-Time (HEFT) algorithms based on deadline constraint and resource utilization. Our experimental results demonstrate that the proposed T-CCWSA outperforms current state-of-the-art heuristics with the criteria of achieving the deadline constraint, minimizing the cost of execution and resource efficiency.} } | G32: {=INDIRECT("Venues!C" & MATCH(B32,Venues!A:A,0))} -> Elsevier
A33: 30 | B33: =Venues!A20 -> 18 | C33: Uncertainty-aware scheduling of real-time workflows under deadline constraints on multi-cloud systems | D33: 2022 | E33: Real-time Workflows Scheduling on Multi-Cloud (RWSMC) | F33: article{30, author = {Xu, Jin and Yu, Huiqun and Fan, Guisheng and Zhang, Jiayin}, title = {Uncertainty-aware scheduling of real-time workflows under deadline constraints on multi-cloud systems}, journal = {Concurrency and Computation: Practice and Experience}, volume = {35}, number = {5}, pages = {e7562}, keywords = {cloud computing, real-time workflows, multi-cloud systems, uncertain task execution time}, doi = {https://doi.org/10.1002/cpe.7562}, url = {https://onlinelibrary.wiley.com/doi/abs/10.1002/cpe.7562}, eprint = {https://onlinelibrary.wiley.com/doi/pdf/10.1002/cpe.7562}, abstract = {Summary The elasticity and pay-as-you-go features of cloud computing are popular with customers, and more and more workflow applications are migrating to cloud platforms. Many workflow scheduling algorithms aim to obtain minimal rental costs. However, most of the existing research assumes that task execution time is deterministic. In fact, due to the performance fluctuations of VMs, the task execution time is uncertain before scheduling. Furthermore, many works ignore the cost savings given by multi-cloud systems. To this end, this paper provides a scheduling framework for real-time workflows. The framework includes four main components: the workflow analyzer, task pool, task allocation controller, and resource manager. Then based on the framework, we propose the RWSMC heuristic algorithm. The algorithm's goal is to minimize the total rental cost while satisfying the deadline constraints and ensuring the reliability of task execution. The RWSMC algorithm reduces the cost by selecting the appropriate billing mechanism based on the task's execution time and mitigates the impact of uncertain execution time by scheduling the task to the VM with the shortest predicted start time. Simulation experiments demonstrate that our proposed algorithm outperforms three recent state-of-the-art scheduling algorithms in the total rental cost, deadline violation rate, and VM resource utilization.}, year = {2023} } | G33: {=INDIRECT("Venues!C" & MATCH(B33,Venues!A:A,0))} -> Wiley
A34: 31 | B34: =Venues!A21 -> 19 | C34: Versatile provisioning and workflow scheduling in WaaS under cost and deadline constraints for cloud computing | D34: 2018 | F34: article{31, author = {Partheeban, Pon. and Kavitha, V.}, title = {Versatile provisioning and workflow scheduling in WaaS under cost and deadline constraints for cloud computing}, journal = {Transactions on Emerging Telecommunications Technologies}, volume = {30}, number = {1}, pages = {e3527}, doi = {https://doi.org/10.1002/ett.3527}, url = {https://onlinelibrary.wiley.com/doi/abs/10.1002/ett.3527}, eprint = {https://onlinelibrary.wiley.com/doi/pdf/10.1002/ett.3527}, note = {e3527 ETT-18-0242.R1}, abstract = {Abstract Cloud computing environment delivers resources and services via a pay-as-you-go billing model, and scheduling workflows have become a major application for distributed systems. An efficient scheduling is very challenging in a cloud to achieve minimum overhead, low cost, and high utilization of resources within the deadline. Workflow as a service (WaaS) provides a simple cost successive way to use the workflow applications in the cloud. This paper introduces a Gang of Tasks (GoTs)–based dynamic scheduling technique for scheduling the workflow to reduce the cost of renting virtual machines (VMs) under the deadline constraints in the WaaS environment. First, the GoTs strategy groups the workflows based on the priority and dependency of data. It schedules similar tasks into the same gang to execute the task from the gang simultaneously to the VMs. After scheduling the task in the GoTs, the deadline is distributed among all the gangs in the workflow. Then, the versatile resources are provisioned, dynamically depending upon the usage of containers in the VMs. The simulation results validate the ability to satisfy the deadline constraints and cost deficiencies of the proposed method as compared to the state-of-the-art methods.}, year = {2019} } | G34: {=INDIRECT("Venues!C" & MATCH(B34,Venues!A:A,0))} -> Wiley
A35: 32 | B35: =Venues!A22 -> 20 | C35: Multi-criteria scheduling of scientific workflows in the Workflow as a Service platform | D35: 2023 | E35: Multi-Criteria Scientific Workflows (MCSW) | F35: article{32, title = {Multi-criteria scheduling of scientific workflows in the Workflow as a Service platform}, journal = {Computers and Electrical Engineering}, volume = {105}, pages = {108458}, year = {2023}, issn = {0045-7906}, doi = {https://doi.org/10.1016/j.compeleceng.2022.108458}, url = {https://www.sciencedirect.com/science/article/pii/S0045790622006735}, author = {Anurina Tarafdar and Kamalesh Karmakar and Rajib K Das and Sunirmal Khatua}, keywords = {Workflow, Container, Energy, Workflow as a service (WaaS), Cloud computing, Resource scheduling}, abstract = {The increasing use of workflows in various fields of science has led to the development of the Workflow as a Service (WaaS) platform, which provides workflow execution as a service to the users. The WaaS platform must use appropriate resource provisioning, sharing, and scheduling, to properly allocate the workflow tasks to the Cloud resources and fulfill the scheduling objectives. In this paper, we have proposed a novel workflow scheduling approach for the WaaS platform that reduces the average makespan of the workflows, improves energy efficiency, and reduces the resource renting cost of the Cloud resources. Our scheduling model consists of containers, virtual machines (VMs), and hosts. We have also proposed a suitable scaling policy for the Cloud resources to improve resource utilization. Extensive simulations with real-world workflows and comparison with some state-of-the-art algorithms show the efficacy of our approach in improving performance and energy efficiency while reducing the monetary cost.} } | G35: {=INDIRECT("Venues!C" & MATCH(B35,Venues!A:A,0))} -> Elsevier
A36: 33 | B36: =Venues!A15 -> 13 | C36: Weighted double deep Q-network based reinforcement learning for bi-objective multi-workflow scheduling in the cloud | D36: 2022 | E36: Weighted Double Deep Q-Network based Reinforcement Learning algorithm (WDDQN-RL) | F36: article{33, author={Li, Huifang and Huang, Jianghang and Wang, Binyang and Fan, Yushun}, journal={Cluster Computing}, title={Weighted double deep Q-network based reinforcement learning for bi-objective multi-workflow scheduling in the cloud}, year={2022}, volume={25}, number={2}, pages={751-768}, doi={10.1007/s10586-021-03454-6}} | G36: {=INDIRECT("Venues!C" & MATCH(B36,Venues!A:A,0))} -> Springer
A37: 34 | B37: =Venues!A15 -> 13 | C37: Security prioritized multiple workflow allocation model under precedence constraints in cloud computing environment | D37: 2024 | E37: Security Prioritized Multiple Workflow Allocation (SPMWA) | F37: article{34, author={Alam, Mahfooz and Shahid, Mohammad and Mustajab, Suhel}, journal={Cluster Computing}, title={Security prioritized multiple workflow allocation model under precedence constraints in cloud computing environment}, year={2024}, volume={27}, number={1}, pages={341-376}, doi={10.1007/s10586-022-03819-5}} | G37: {=INDIRECT("Venues!C" & MATCH(B37,Venues!A:A,0))} -> Springer
A38: 35 | B38: =Venues!A15 -> 13 | C38: Trust-driven and QoS demand clustering analysis based cloud workflow scheduling strategies | D38: 2014 | F38: article{35, author={Li, Wenjuan and Wu, Jiyi and Zhang, Qifei and Hu, Keyong and Li, Jing}, journal={Cluster Computing}, title={Trust-driven and QoS demand clustering analysis based cloud workflow scheduling strategies}, year={2014}, volume={17}, number={3}, pages={1013-1030}, doi={10.1007/s10586-013-0340-1}} | G38: {=INDIRECT("Venues!C" & MATCH(B38,Venues!A:A,0))} -> Springer
A39: 36 | B39: =Venues!A32 -> 30 | C39: Clustering-based multi-objective optimization considering fairness for multi-workflow scheduling on clouds | D39: 2024 | E39: Depth-First-Search considering Critical Subsequent Task(DFS-CST) | F39: article{36, title = {Clustering-based multi-objective optimization considering fairness for multi-workflow scheduling on clouds}, journal = {Journal of Parallel and Distributed Computing}, volume = {194}, pages = {104968}, year = {2024}, issn = {0743-7315}, doi = {https://doi.org/10.1016/j.jpdc.2024.104968}, url = {https://www.sciencedirect.com/science/article/pii/S0743731524001321}, author = {Feng Li and Wen Jun Tan and Moon Gi Seok and Wentong Cai}, keywords = {Multi-objective optimization, Multi-workflow scheduling, Scheduling fairness, Clustering-based resource allocation}, abstract = {Distributed computing, such as cloud computing, provides promising platforms for orchestrating scientific workflows' tasks based on their sequences and dependencies. Workflow scheduling plays an important role in optimizing concerned objectives for distributed computing, such as minimizing the makespan and cost. Many researchers have focused on optimizing a specific single workflow with multiple objectives. Currently, there are few studies on multi-workflow scheduling, with most research focusing on objectives such as cost and makespan. However, multi-workflow scheduling requires the design of specific objectives that reflect the unique characteristics of multiple workflows. On the other hand, clustering-based approaches have garnered significant attention in the field of workflow scheduling over distributed computing resources due to their advantage in reducing data communication among tasks. Despite this, the effectiveness of clustering-based algorithms has not been extensively studied and validated in the context of multi-objective multi-workflow scheduling models. Motivated by these factors, we propose an approach for multiple workflows' multi-objective optimization (MOO), considering the new defined metric, fairness. We first mathematically formulate the fairness and define a fairness-involved MOO model. Then, we propose an advanced clustering-based resource optimization strategy in multiple workflow runs. Experimental results show that the proposed approach performs better than the compared algorithms without significant compromise of the overall makespan and cost as well as individual fairness, which can guide the simulation workflow scheduling on clouds.} } | G39: {=INDIRECT("Venues!C" & MATCH(B39,Venues!A:A,0))} -> Elsevier
A40: 37 | B40: =Venues!A23 -> 21 | C40: WaaS: Workflow-as-a-Service for the Cloud with Scheduling of Continuous and Data-Intensive Workflows | D40: 2016 | E40: sidering Critical Subsequent Task (DFS-CST) | F40: article{37, author = {Esteves, Sergio and Veiga, Lui­s}, title = "{WaaS: Workflow-as-a-Service for the Cloud with Scheduling of Continuous and Data-Intensive Workflows}", journal = {The Computer Journal}, volume = {59}, number = {3}, pages = {371-383}, year = {2015}, month = {01}, abstract = "{Data-intensive and long-lasting applications running in the form of workflows are being increasingly dispatched to cloud computing systems. Current scheduling approaches for graphs of dependencies fail to deliver high resource efficiency while keeping computation costs low, especially for continuous data processing workflows, where the scheduler does not perform any reasoning about the impact new input data may have in the workflow final output. To face such a challenge, we introduce a new scheduling criterion, Quality-of-Data (QoD), which describes the requirements about the data that are worthy of the triggering of tasks in workflows. Based on the QoD notion, we propose a novel service-oriented scheduler planner, for continuous data processing workflows, that is capable of enforcing QoD constraints and guide the scheduling to attain resource efficiency, overall controlled performance and task prioritization. To contrast the advantages of our scheduling model against others, we developed WaaS (Workflow-as-a-Service), a workflow coordinator system for the Cloud where data is shared among tasks via cloud columnar database.}", issn = {0010-4620}, doi = {10.1093/comjnl/bxu158}, url = {https://doi.org/10.1093/comjnl/bxu158}, eprint = {https://academic.oup.com/comjnl/article-pdf/59/3/371/7902553/bxu158.pdf}, } | G40: {=INDIRECT("Venues!C" & MATCH(B40,Venues!A:A,0))} -> Oxford Academic
A41: 38 | B41: =Venues!A24 -> 22 | C41: Dynamic Scheduling Stochastic Multiworkflows With Deadline Constraints in Clouds | D41: 2023 | E41: Stochastic Multi-Workflows Dynamic Scheduling Algorithm (SMWDSA) | F41: article{38, author={Ye, Lingjuan and Xia, Yuanqing and Yang, Liwen and Zhan, Yufeng}, journal={IEEE Transactions on Automation Science and Engineering}, title={Dynamic Scheduling Stochastic Multiworkflows With Deadline Constraints in Clouds}, year={2023}, volume={20}, number={4}, pages={2594-2606}, keywords={Task analysis;Cloud computing;Costs;Dynamic scheduling;Job shop scheduling;Heuristic algorithms;Schedules;Dynamic scheduling;multi-workflows;deadline constraints;cloud computing}, doi={10.1109/TASE.2022.3204313}} | G41: {=INDIRECT("Venues!C" & MATCH(B41,Venues!A:A,0))} -> IEEE
...

Sheet Negotiation and Pricing Taxonom
A1: PID | C1: Negotiation and Pricing
C2: Qos Requirements | E2: Workflow Arrival | I2: Negotiation | K2: Pricing
C3: Multi-Criteria | D3: Constrained | E3: Online | F3: Batch | G3: Ensemble | H3: Periodic | I3: Static | J3: Dynamic | K3: Pre-pricing | L3: Post-pricing
A5: =Papers!A3 -> 1 | D5: P | H5: P
A6: =Papers!A4 -> 2 | D6: P | E6: P | I6: P | K6: P | L6: P
A7: =Papers!A5 -> 3 | D7: P | E7: P
A8: =Papers!A6 -> 4 | D8: P | E8: P
A9: =Papers!A7 -> 5 | D9: P | H9: P
A10: =Papers!A8 -> 6 | D10: P | E10: P
A11: =Papers!A9 -> 7 | C11: P | E11: P
A12: =Papers!A10 -> 8 | D12: P | E12: P
A13: =Papers!A11 -> 9 | D13: P | E13: P
A14: =Papers!A12 -> 10 | C14: P | E14: P
A15: =Papers!A13 -> 11 | D15: P | E15: P
A16: =Papers!A14 -> 12 | D16: P | E16: P
A17: =Papers!A15 -> 13 | D17: P | E17: P
A18: =Papers!A16 -> 14 | D18: P | E18: P
A19: =Papers!A17 -> 15 | D19: P | F19: P
A20: =Papers!A18 -> 16 | D20: P | E20: P
A21: =Papers!A19 -> 17 | C21: P | F21: P
A22: =Papers!A20 -> 18 | D22: P | F22: P
A23: =Papers!A21 -> 19 | D23: P | E23: P
A24: =Papers!A22 -> 20 | D24: P | G24: P
A25: =Papers!A23 -> 21 | D25: P | G25: P
A26: =Papers!A24 -> 21-b | D26: P | G26: P
A27: =Papers!A25 -> 22 | D27: P | E27: P
A28: =Papers!A26 -> 23 | D28: P | E28: P
A29: =Papers!A27 -> 24 | D29: P | E29: P
A30: =Papers!A28 -> 25 | D30: P | F30: P
A31: =Papers!A29 -> 26 | D31: P | E31: P
A32: =Papers!A30 -> 27 | D32: P | E32: P
A33: =Papers!A31 -> 28 | D33: P | E33: P
A34: =Papers!A32 -> 29 | D34: P | E34: P
A35: =Papers!A33 -> 30 | D35: P | E35: P
A36: =Papers!A34 -> 31 | D36: P | E36: P
A37: =Papers!A35 -> 32 | C37: P | F37: P
A38: =Papers!A36 -> 33 | C38: P | F38: P
A39: =Papers!A37 -> 34 | C39: P | F39: P
A40: =Papers!A38 -> 35 | D40: P | F40: P
A41: =Papers!A39 -> 36 | C41: P | F41: P
...

Sheet Task Scheduler Taxonomy
A1: PID | C1: Task Scheduling
C2: Task Type | E2: Task Concurrency | G2: Task Time Estimation | J2: Data Transmission | L2: Scheduling Criteria | T2: Scheduling Type | X2: Scheduling Strategy
C3: Rigid | D3: Flexible | E3: Single | F3: Multiple | G3: Fixed | H3: Probabilistic | I3: Fuzzy | J3: Direct | K3: Indirect | L3: Time | M3: Cost | N3: Security | O3: Privacy | P3: Reliability | Q3: Fairness | R3: Energy | S3: Utilization | T3: Static | V3: Dynamic | X3: Heuristic | Y3: Meta-heuristic | Z3: Game Theory | AA3: Reinforcement Learning | AB3: MCDM | AC3: Mathematical Optimization
T4: One-by-one | U4: Combined | V4: Immediate | W4: Periodic
A6: =Papers!A3 -> 1 | C6: P | F6: P | H6: P | K6: P | L6: P | M6: P | U6: P | W6: P | X6: P
A7: =Papers!A4 -> 2 | C7: P | F7: P | H7: P | K7: P | L7: P | M7: P | W7: P | X7: P
A8: =Papers!A5 -> 3 | D8: P | E8: P | G8: P | J8: P | L8: P | M8: P | U8: P | Y8: P
A9: =Papers!A6 -> 4 | D9: P | E9: P | H9: P | J9: P | L9: P | M9: P | Q9: P | S9: P | V9: P | X9: P
A10: =Papers!A7 -> 5 | D10: P | E10: P | G10: P | L10: P | M10: P | U10: P | X10: P
A11: =Papers!A8 -> 6 | D11: P | E11: P | H11: P | J11: P | L11: P | M11: P | V11: P | X11: P
A12: =Papers!A9 -> 7 | D12: P | E12: P | G12: P | L12: P | M12: P | V12: P | AA12: P
A13: =Papers!A10 -> 8 | D13: P | E13: P | H13: P | K13: P | L13: P | M13: P | S13: P | V13: P | X13: P
A14: =Papers!A11 -> 9 | D14: P | E14: P | G14: P | J14: P | L14: P | M14: P | P14: P | R14: P | V14: P | X14: P
A15: =Papers!A12 -> 10 | D15: P | E15: P | G15: P | J15: P | L15: P | M15: P | V15: P | AB15: P
A16: =Papers!A13 -> 11 | D16: P | E16: P | H16: P | J16: P | L16: P | S16: P | V16: P | X16: P
A17: =Papers!A14 -> 12 | D17: P | E17: P | G17: P | J17: P | L17: P | M17: P | S17: P | V17: P | X17: P
A18: =Papers!A15 -> 13 | D18: P | E18: P | G18: P | K18: P | L18: P | M18: P | V18: P | X18: P
A19: =Papers!A16 -> 14 | D19: P | E19: P | H19: P | J19: P | L19: P | M19: P | V19: P | X19: P
A20: =Papers!A17 -> 15 | C20: P | E20: P | G20: P | L20: P | M20: P | Q20: P | T20: P | X20: P
A21: =Papers!A18 -> 16 | C21: P | E21: P | I21: P | K21: P | L21: P | M21: P | W21: P | X21: P
A22: =Papers!A19 -> 17 | D22: P | E22: P | G22: P | L22: P | M22: P | Q22: P | U22: P | Z22: P
A23: =Papers!A20 -> 18 | D23: P | E23: P | G23: P | L23: P | M23: P | T23: P | Y23: P
A24: =Papers!A21 -> 19 | D24: P | E24: P | G24: P | K24: P | L24: P | M24: P | W24: P | X24: P
A25: =Papers!A22 -> 20 | C25: P | E25: P | G25: P | K25: P | L25: P | M25: P | W25: P | X25: P
A26: =Papers!A23 -> 21 | C26: P | E26: P | H26: P | K26: P | L26: P | M26: P | V26: P | X26: P
A27: =Papers!A24 -> 21-b | C27: P | E27: P | H27: P | K27: P | L27: P | M27: P | T27: P | X27: P
A28: =Papers!A25 -> 22 | D28: P | E28: P | G28: P | K28: P | L28: P | M28: P | W28: P | X28: P
A29: =Papers!A26 -> 23 | D29: P | E29: P | G29: P | J29: P | L29: P | M29: P | V29: P | X29: P
A30: =Papers!A27 -> 24 | D30: P | E30: P | H30: P | K30: P | L30: P | M30: P | R30: P | V30: P | X30: P
A31: =Papers!A28 -> 25 | D31: P | E31: P | G31: P | L31: P | S31: P | V31: P | X31: P
A32: =Papers!A29 -> 26 | D32: P | E32: P | G32: P | K32: P | L32: P | M32: P | V32: P | AB32: P
A33: =Papers!A30 -> 27 | D33: P | E33: P | G33: P | J33: P | L33: P | M33: P | V33: P | X33: P
A34: =Papers!A31 -> 28 | D34: P | E34: P | G34: P | K34: P | M34: P | S34: P | V34: P | X34: P
A35: =Papers!A32 -> 29 | D35: P | E35: P | G35: P | J35: P | L35: P | M35: P | S35: P | V35: P | AB35: P
A36: =Papers!A33 -> 30 | D36: P | E36: P | H36: P | J36: P | L36: P | M36: P | V36: P | X36: P
A37: =Papers!A34 -> 31 | D37: P | E37: P | H37: P | K37: P | L37: P | M37: P | V37: P | X37: P
A38: =Papers!A35 -> 32 | D38: P | F38: P | G38: P | J38: P | L38: P | M38: P | R38: P | S38: P | U38: P | X38: P
A39: =Papers!A36 -> 33 | D39: P | E39: P | G39: P | K39: P | L39: P | M39: P | W39: P | AA39: P
A40: =Papers!A37 -> 34 | D40: P | E40: P | G40: P | J40: P | L40: P | N40: P | P40: P | U40: P | X40: P
A41: =Papers!A38 -> 35 | D41: P | E41: P | G41: P | L41: P | M41: P | N41: P | T41: P | X41: P
...

Sheet Resource Provisioner Taxonomy
A1: PID | C1: Resource Provisioning
C2: Resource Type | F2: Resource Diversity | H2: Resource Pricing | K2: Provisioning Timing | M2: Provisining Delay | O2: Deployment Model
C3: VM | D3: Container | E3: Function | F3: Heterogeneous | G3: Homogeneous | H3: On-demand | I3: Spot | J3: Reserved | K3: As-needed | L3: Periodic | M3: Delay-aware | N3: Instantaneous | O3: Single-Cloud | P3: Multi-Cloud | Q3: Hybrid Cloud
A5: =Papers!A3 -> 1 | D5: P | G5: P | H5: P | J5: P | K5: P | M5: P | O5: P
A6: =Papers!A4 -> 2 | D6: P | F6: P | H6: P | I6: P | L6: P | M6: P | O6: P
A7: =Papers!A5 -> 3 | C7: P | F7: P | H7: P | K7: P | N7: P | O7: P
A8: =Papers!A6 -> 4 | C8: P | F8: P | H8: P | K8: P | M8: P | O8: P
A9: =Papers!A7 -> 5 | C9: P | F9: P | J9: P | L9: P | N9: P | O9: P
A10: =Papers!A8 -> 6 | C10: P | F10: P | H10: P | K10: P | N10: P | O10: P
A11: =Papers!A9 -> 7 | C11: P | F11: P | H11: P | K11: P | N11: P | O11: P
A12: =Papers!A10 -> 8 | C12: P | F12: P | H12: P | K12: P | N12: P | O12: P
A13: =Papers!A11 -> 9 | C13: P | F13: P | H13: P | K13: P | N13: P | P13: P
A14: =Papers!A12 -> 10 | C14: P | F14: P | H14: P | K14: P | N14: P | O14: P
A15: =Papers!A13 -> 11 | C15: P | F15: P | J15: P | O15: P
A16: =Papers!A14 -> 12 | C16: P | F16: P | H16: P | K16: P | M16: P | O16: P
A17: =Papers!A15 -> 13 | C17: P | F17: P | H17: P | K17: P | M17: P | O17: P
A18: =Papers!A16 -> 14 | C18: P | F18: P | H18: P | O18: P
A19: =Papers!A17 -> 15 | C19: P | F19: P | H19: P | K19: P | N19: P | O19: P
A20: =Papers!A18 -> 16 | C20: P | G20: P | H20: P | J20: P | K20: P | N20: P | O20: P
A21: =Papers!A19 -> 17 | C21: P | F21: P | H21: P | P21: P
A22: =Papers!A20 -> 18 | C22: P | F22: P | H22: P | K22: P | N22: P | O22: P
A23: =Papers!A21 -> 19 | D23: P | F23: P | H23: P | K23: P | M23: P | O23: P
A24: =Papers!A22 -> 20 | C24: P | G24: P | H24: P | I24: P | L24: P | M24: P | O24: P
A25: =Papers!A23 -> 21 | C25: P | G25: P | H25: P | L25: P | M25: P | O25: P
A26: =Papers!A24 -> 21-b | C26: P | G26: P | H26: P | K26: P | M26: P | O26: P
A27: =Papers!A25 -> 22 | D27: P | F27: P | H27: P | K27: P | M27: P | O27: P
A28: =Papers!A26 -> 23 | C28: P | F28: P | H28: P | K28: P | N28: P | O28: P
A29: =Papers!A27 -> 24 | D29: P | F29: P | H29: P | K29: P | M29: P | O29: P
A30: =Papers!A28 -> 25 | C30: P | F30: P | H30: P | K30: P | N30: P | O30: P
A31: =Papers!A29 -> 26 | C31: P | F31: P | H31: P | K31: P | N31: P | O31: P
A32: =Papers!A30 -> 27 | C32: P | F32: P | J32: P | O32: P
A33: =Papers!A31 -> 28 | C33: P | F33: P | J33: P | O33: P
A34: =Papers!A32 -> 29 | C34: P | F34: P | H34: P | K34: P | M34: P | O34: P
A35: =Papers!A33 -> 30 | C35: P | F35: P | H35: P | K35: P | M35: P | P35: P
A36: =Papers!A34 -> 31 | D36: P | F36: P | H36: P | K36: P | M36: P | O36: P
A37: =Papers!A35 -> 32 | D37: P | F37: P | H37: P | L37: P | M37: P | O37: P
A38: =Papers!A36 -> 33 | C38: P | F38: P | H38: P | O38: P
A39: =Papers!A37 -> 34 | C39: P | F39: P | H39: P | K39: P | N39: P | O39: P
A40: =Papers!A38 -> 35 | C40: P | F40: P | H40: P | P40: P
A41: =Papers!A39 -> 36 | C41: P | F41: P | J41: P | O41: P
...

Sheet Monitoring and Fault Tolerance 
A1: PID | C1: Monitoring and Fault Tolerance
C2: Checkpointing | D2: Re-execution | E2: Replication
A4: =Papers!A3 -> 1
A5: =Papers!A4 -> 2 | C5: P
A6: =Papers!A5 -> 3
A7: =Papers!A6 -> 4
A8: =Papers!A7 -> 5
A9: =Papers!A8 -> 6
A10: =Papers!A9 -> 7
A11: =Papers!A10 -> 8
A12: =Papers!A11 -> 9 | E12: P
A13: =Papers!A12 -> 10
A14: =Papers!A13 -> 11
